<?xml version="1.0"?>
<!-- This URDF was automatically created by SolidWorks to URDF Exporter! Originally created by Stephen Brawner (brawner@gmail.com) 
     Commit Version: 1.6.0-4-g7f85cfe  Build Version: 1.6.7995.38578
     For more information, please see http://wiki.ros.org/sw_urdf_exporter -->
<robot name="delivery" xmlns:xacro="http://ros.org/wiki/xacro">
  
  <xacro:arg name="is_ignition" default="true" />
  <!-- Include Gazebo Parameters-->
  <xacro:include filename="$(find delivery_description)/urdf/delivery_gazebo.xacro"/>

  <!-- ROS2 Control-->
  <xacro:include filename="$(find delivery_description)/urdf/delivery_ros2_control.xacro"/>

  <link name="base_footprint" />
  <link name="base_link">
    <inertial>
      <origin xyz="0 0 -0.05" rpy="0 0 0" />
      <mass
        value="50" />
      <inertia
        ixx="0.190013298612022"
        ixy="-1.97362982292358E-06"
        ixz="1.09139279405602E-15"
        iyy="0.194102599343596"
        iyz="-1.36853189937296E-17"
        izz="0.328271696632787" />
    </inertial>
    <visual>
      <origin
        xyz="0 0 0"
        rpy="0 0 0" />
      <geometry>
        <mesh filename="package://delivery_description/meshes/base_link.STL" />
      </geometry>
      <material
        name="">
        <color
          rgba="0.1 0.1 0.1 1" />
      </material>
    </visual>
    <collision>
      <origin
        xyz="0 0 0"
        rpy="0 0 0" />
      <geometry>
        <mesh filename="package://delivery_description/meshes/base_link.STL" />
      </geometry>
    </collision>
  
  </link>
  <joint name="base_joint" type="fixed">
      <parent link="base_footprint" />
      <child link="base_link" />
      <origin xyz="0 0 0.21" rpy="0 0 0"/>
  </joint>

  <link name="front_left_wheel">
    <inertial>
      <origin
        xyz="0 0 0"
        rpy="1.5708 0 0" />
      <mass
        value="0.26661498322291" />
      <inertia
        ixx="8.05457942683617E-05"
        ixy="-2.79543633711077E-15"
        ixz="3.37021382345757E-14"
        iyy="8.05457942749361E-05"
        iyz="1.10037676592356E-14"
        izz="9.3195603890608E-05" />
    </inertial>
    <visual>
      <origin
        xyz="0 0.03 0"
        rpy="1.5708 0 0" />
      <geometry>
        <mesh filename="package://delivery_description/meshes/Front_Left_Wheel.STL" />
      </geometry>
      <material
        name="">
        <color
          rgba="0.792156862745098 0.819607843137255 0.933333333333333 1" />
      </material>
    </visual>
    <collision>
      <origin
        xyz="0 0.03 0"
        rpy="1.5708 0 0" />
      <geometry>
        <mesh filename="package://delivery_description/meshes/Front_Left_Wheel.STL" />
      </geometry>
    </collision>
  </link>
  <joint name="front_left_wheel_joint"
    type="continuous">
    <origin
      xyz="0.19721 0.24498 -0.15567"
      rpy="0 0 0" />
    <parent
      link="base_link" />
    <child
      link="front_left_wheel" />
    <axis
      xyz="0 1 0" />
    <limit
      effort="150"
      velocity="50" />
    <dynamics
      damping="0.1"
      friction="0.1" />
  </joint>

  <link name="front_right_wheel">
    <inertial>
      <origin
        xyz="0 0 0"
        rpy="1.5708 0 0" />
      <mass
        value="0.266614983222909" />
      <inertia
        ixx="8.0545794268312E-05"
        ixy="-2.80019667850405E-15"
        ixz="3.37091076216657E-14"
        iyy="8.05457942748739E-05"
        iyz="1.10097155984234E-14"
        izz="9.31956038905408E-05" />
    </inertial>
    <visual>
      <origin
        xyz="0 -0.03 0"
        rpy="1.5708 0 0" />
      <geometry>
        <mesh filename="package://delivery_description/meshes/Right_Front_Wheel.STL" />
      </geometry>
      <material
        name="">
        <color
          rgba="0.792156862745098 0.819607843137255 0.933333333333333 1" />
      </material>
    </visual>
    <collision>
      <origin
        xyz="0 -0.03 0"
        rpy="1.5708 0 0" />
      <geometry>
        <mesh filename="package://delivery_description/meshes/Right_Front_Wheel.STL" />
      </geometry>
    </collision>
  </link>
  <joint name="front_right_wheel_joint"
    type="continuous">
    <origin
      xyz="0.19721 -0.24502 -0.15567"
      rpy="0 0 0" />
    <parent
      link="base_link" />
    <child
      link="front_right_wheel" />
    <axis
      xyz="0 1 0" />
    <limit
      effort="150"
      velocity="50" />
    <dynamics
      damping="0.1"
      friction="0.1" />
  </joint>

  <link name="back_left_wheel">
    <inertial>
      <origin
        xyz="0 0 0"
        rpy="1.5708 0 0" />
      <mass
        value="0.266614983222911" />
      <inertia
        ixx="8.05457942683817E-05"
        ixy="-2.79572074526522E-15"
        ixz="3.36987949955329E-14"
        iyy="8.05457942749372E-05"
        iyz="1.10377338930185E-14"
        izz="9.31956038906202E-05" />
    </inertial>
    <visual>
      <origin
        xyz="0 0.03 0"
        rpy="1.5708 0 0" />
      <geometry>
        <mesh filename="package://delivery_description/meshes/Left_Back_wheel.STL" />
      </geometry>
      <material
        name="">
        <color
          rgba="0.792156862745098 0.819607843137255 0.933333333333333 1" />
      </material>
    </visual>
    <collision>
      <origin
        xyz="0 0.03 0"
        rpy="1.5708 0 0" />
      <geometry>
        <mesh filename="package://delivery_description/meshes/Left_Back_wheel.STL" />
      </geometry>
    </collision>
  </link>
  <joint name="back_left_wheel_joint"
    type="continuous">
    <origin
      xyz="-0.19721 0.24498 -0.15567"
      rpy="0 0 0" />
    <parent
      link="base_link" />
    <child
      link="back_left_wheel" />
    <axis
      xyz="0 1 0" />
    <limit
      effort="150"
      velocity="50" />
    <dynamics
      damping="0.1"
      friction="0.1" />
  </joint>
  <link name="back_right_wheel">
    <inertial>
      <origin
        xyz="0 0 0"
        rpy="1.5708 0 0" />
      <mass
        value="0.266614983222911" />
      <inertia
        ixx="8.05457942683914E-05"
        ixy="-2.79608823622019E-15"
        ixz="3.36986637054261E-14"
        iyy="8.05457942749527E-05"
        iyz="1.10332704558511E-14"
        izz="9.31956038906356E-05" />
    </inertial>
    <visual>
      <origin
        xyz="0 -0.03 0"
        rpy="1.5708 0 0" />
      <geometry>
        <mesh filename="package://delivery_description/meshes/Right_Bach_Wheel.STL" />
      </geometry>
      <material
        name="">
        <color
          rgba="0.792156862745098 0.819607843137255 0.933333333333333 1" />
      </material>
    </visual>
    <collision>
      <origin
        xyz="0 -0.03 0"
        rpy="1.5708 0 0" />
      <geometry>
        <mesh filename="package://delivery_description/meshes/Right_Bach_Wheel.STL" />
      </geometry>
    </collision>
  </link>
  <joint name="back_right_wheel_joint"
    type="continuous">
    <origin
      xyz="-0.19721 -0.24502 -0.15567"
      rpy="0 0 0" />
    <parent
      link="base_link" />
    <child
      link="back_right_wheel" />
    <axis
      xyz="0 1 0" />
    <limit
      effort="150"
      velocity="50" />
    <dynamics
      damping="0.1"
      friction="0.1" />
  </joint>

  <link name="imu_link">
    <inertial>
      <origin xyz="-0.00552433659106688 0.000168210391520346 0.000514000497342681" rpy="0 0 0" />
      <mass value="0.000528415362211671" />
      <inertia ixx="1.46176048428261E-08" ixy="1.40015117949421E-10" ixz="-1.99633872937403E-12"
               iyy="8.59662482954888E-09" iyz="7.52375112767959E-12"
               izz="2.30279421279312E-08" />
    </inertial>
    <visual>
      <origin xyz="0 0 0" rpy="0 0 0" />
      <geometry>
        <mesh filename="package://delivery_description/meshes/imu_link.STL" />
      </geometry>
      <material name="">
        <color rgba="0.792156862745098 0.819607843137255 0.933333333333333 1" />
      </material>
    </visual>
    <collision>
      <origin xyz="0 0 0" rpy="0 0 0" />
      <geometry>
        <mesh filename="package://delivery_description/meshes/imu_link.STL" />
      </geometry>
    </collision>
  </link>
  
  <joint name="imu_joint" type="fixed">
    <origin xyz="0 0 0" rpy="0 0 0" />
    <parent link="base_link" />
    <child link="imu_link" />
    <axis xyz="0 0 0" />
  </joint>




</robot>